Workbook

Sheet Sales cleaned
A1: SaleID | B1: SaleDate | C1: ProductID | D1: Quantity | E1: UnitPrice | F1: RegionID | G1: dataqaulity_status | H1: Revenue | I1: productname
A2: S1001 | B2: 46114 | C2: P101 | D2: 1 | E2: 49.99 | F2: R01 | H2: =IF(D2="","",D2*E2) -> 49.99 | I2: =_xlfn.XLOOKUP(C2,Products!$A$2:$A$9,Products!$B$2:$B$9,"Not Found") -> Coffee Maker
A3: S1002 | B3: 46121 | C3: P106 | D3: 3 | E3: 39.99 | F3: R04 | H3: =IF(D3="","",D3*E3) -> 119.97 | I3: =_xlfn.XLOOKUP(C3,Products!$A$2:$A$9,Products!$B$2:$B$9,"Not Found") -> Headphones
A4: S1003 | B4: 46128 | C4: P103 | D4: 5 | E4: 25 | F4: R03 | H4: =IF(D4="","",D4*E4) -> 125 | I4: =_xlfn.XLOOKUP(C4,Products!$A$2:$A$9,Products!$B$2:$B$9,"Not Found") -> Desk Lamp
A5: S1004 | B5: 46135 | C5: P108 | D5: 2 | E5: 18.99 | F5: R02 | H5: =IF(D5="","",D5*E5) -> 37.98 | I5: =_xlfn.XLOOKUP(C5,Products!$A$2:$A$9,Products!$B$2:$B$9,"Not Found") -> Desk Organizer
A6: S1005 | B6: 46117 | C6: P105 | D6: 4 | E6: 14.5 | F6: R01 | H6: =IF(D6="","",D6*E6) -> 58 | I6: =_xlfn.XLOOKUP(C6,Products!$A$2:$A$9,Products!$B$2:$B$9,"Not Found") -> Water Bottle
A7: S1006 | B7: 46124 | C7: P102 | D7: 1 | E7: 59.99 | F7: R04 | H7: =IF(D7="","",D7*E7) -> 59.99 | I7: =_xlfn.XLOOKUP(C7,Products!$A$2:$A$9,Products!$B$2:$B$9,"Not Found") -> Blender
A8: S1007 | B8: 46131 | C8: P107 | D8: 3 | E8: 9.99 | F8: R03 | H8: =IF(D8="","",D8*E8) -> 29.97 | I8: =_xlfn.XLOOKUP(C8,Products!$A$2:$A$9,Products!$B$2:$B$9,"Not Found") -> USB Cable
A9: S1008 | B9: 46138 | C9: P104 | D9: 5 | E9: 5.99 | F9: R02 | H9: =IF(D9="","",D9*E9) -> 29.95 | I9: =_xlfn.XLOOKUP(C9,Products!$A$2:$A$9,Products!$B$2:$B$9,"Not Found") -> Notebook
A10: S1009 | B10: 46120 | C10: P101 | D10: 2 | E10: 49.99 | F10: R01 | H10: =IF(D10="","",D10*E10) -> 99.98 | I10: =_xlfn.XLOOKUP(C10,Products!$A$2:$A$9,Products!$B$2:$B$9,"Not Found") -> Coffee Maker
A11: S1010 | B11: 46127 | C11: P106 | D11: 4 | E11: 39.99 | F11: R04 | H11: =IF(D11="","",D11*E11) -> 159.96 | I11: =_xlfn.XLOOKUP(C11,Products!$A$2:$A$9,Products!$B$2:$B$9,"Not Found") -> Headphones
A12: S1011 | B12: 46134 | C12: P103 | D12: 1 | E12: 25 | F12: R03 | H12: =IF(D12="","",D12*E12) -> 25 | I12: =_xlfn.XLOOKUP(C12,Products!$A$2:$A$9,Products!$B$2:$B$9,"Not Found") -> Desk Lamp
A13: S1012 | B13: 46116 | C13: P108 | D13: 3 | E13: 18.99 | F13: R02 | H13: =IF(D13="","",D13*E13) -> 56.97 | I13: =_xlfn.XLOOKUP(C13,Products!$A$2:$A$9,Products!$B$2:$B$9,"Not Found") -> Desk Organizer
... A24: S1023 | B24: 46148 | C24: P108 | D24: 5 | E24: 18.99 | F24: R04 | H24: =IF(D24="","",D24*E24) -> 94.95 | I24: =_xlfn.XLOOKUP(C24,Products!$A$2:$A$9,Products!$B$2:$B$9,"Not Found") -> Desk Organizer
A25: S1024 | B25: 46155 | C25: P105 | E25: 14.5 | F25: R03 | G25: missing quantity- revenue unknown | H25: =IF(D25="","",D25*E25) | I25: =_xlfn.XLOOKUP(C25,Products!$A$2:$A$9,Products!$B$2:$B$9,"Not Found") -> Water Bottle
A26: S1025 | B26: 46193 | C26: P103 | D26: 4 | E26: 25 | F26: R03 | H26: =IF(D26="","",D26*E26) -> 100 | I26: =_xlfn.XLOOKUP(C26,Products!$A$2:$A$9,Products!$B$2:$B$9,"Not Found") -> Desk Lamp
A27: S1026 | B27: 46175 | C27: P108 | D27: 1 | E27: 18.99 | F27: R02 | H27: =IF(D27="","",D27*E27) -> 18.99 | I27: =_xlfn.XLOOKUP(C27,Products!$A$2:$A$9,Products!$B$2:$B$9,"Not Found") -> Desk Organizer
A28: S1027 | B28: 46182 | C28: P105 | D28: 3 | E28: 14.5 | F28: R01 | H28: =IF(D28="","",D28*E28) -> 43.5 | I28: =_xlfn.XLOOKUP(C28,Products!$A$2:$A$9,Products!$B$2:$B$9,"Not Found") -> Water Bottle
A29: S1028 | B29: 46189 | C29: P102 | D29: 5 | E29: 59.99 | F29: R04 | H29: =IF(D29="","",D29*E29) -> 299.95 | I29: =_xlfn.XLOOKUP(C29,Products!$A$2:$A$9,Products!$B$2:$B$9,"Not Found") -> Blender
A30: S1029 | B30: 46196 | C30: P107 | D30: 2 | E30: 9.99 | F30: R03 | H30: =IF(D30="","",D30*E30) -> 19.98 | I30: =_xlfn.XLOOKUP(C30,Products!$A$2:$A$9,Products!$B$2:$B$9,"Not Found") -> USB Cable
A31: S1030 | B31: 46178 | C31: P104 | D31: 4 | E31: 5.99 | F31: R02 | H31: =IF(D31="","",D31*E31) -> 23.96 | I31: =_xlfn.XLOOKUP(C31,Products!$A$2:$A$9,Products!$B$2:$B$9,"Not Found") -> Notebook
A32: S1031 | B32: 46185 | C32: P101 | D32: 1 | E32: 49.99 | F32: R01 | H32: =IF(D32="","",D32*E32) -> 49.99 | I32: =_xlfn.XLOOKUP(C32,Products!$A$2:$A$9,Products!$B$2:$B$9,"Not Found") -> Coffee Maker
A33: S1032 | B33: 46192 | C33: P106 | D33: 3 | E33: 39.99 | F33: R04 | H33: =IF(D33="","",D33*E33) -> 119.97 | I33: =_xlfn.XLOOKUP(C33,Products!$A$2:$A$9,Products!$B$2:$B$9,"Not Found") -> Headphones
A34: S1033 | B34: 46199 | C34: P103 | D34: 5 | E34: 25 | F34: R03 | H34: =IF(D34="","",D34*E34) -> 125 | I34: =_xlfn.XLOOKUP(C34,Products!$A$2:$A$9,Products!$B$2:$B$9,"Not Found") -> Desk Lamp
A35: S1034 | B35: 46181 | C35: P108 | D35: 2 | E35: 18.99 | F35: R02 | H35: =IF(D35="","",D35*E35) -> 37.98 | I35: =_xlfn.XLOOKUP(C35,Products!$A$2:$A$9,Products!$B$2:$B$9,"Not Found") -> Desk Organizer
A36: S1035 | B36: 46188 | C36: P105 | D36: 4 | E36: 14.5 | F36: R01 | H36: =IF(D36="","",D36*E36) -> 58 | I36: =_xlfn.XLOOKUP(C36,Products!$A$2:$A$9,Products!$B$2:$B$9,"Not Found") -> Water Bottle
A37: S1036 | B37: 46195 | C37: P102 | D37: 1 | E37: 0 | F37: R04 | G37: Confirmed Giveaway | H37: =IF(D37="","",D37*E37) -> 0 | I37: =_xlfn.XLOOKUP(C37,Products!$A$2:$A$9,Products!$B$2:$B$9,"Not Found") -> Blender
A38: S1037 | B38: 46207 | C38: P108 | D38: 3 | E38: 18.99 | F38: R04 | H38: =IF(D38="","",D38*E38) -> 56.97 | I38: =_xlfn.XLOOKUP(C38,Products!$A$2:$A$9,Products!$B$2:$B$9,"Not Found") -> Desk Organizer
A39: S1038 | B39: 46214 | C39: P105 | D39: 5 | E39: 14.5 | F39: R03 | H39: =IF(D39="","",D39*E39) -> 72.5 | I39: =_xlfn.XLOOKUP(C39,Products!$A$2:$A$9,Products!$B$2:$B$9,"Not Found") -> Water Bottle
A40: S1039 | B40: 46221 | C40: P102 | D40: 2 | E40: 59.99 | F40: R02 | H40: =IF(D40="","",D40*E40) -> 119.98 | I40: =_xlfn.XLOOKUP(C40,Products!$A$2:$A$9,Products!$B$2:$B$9,"Not Found") -> Blender
A41: S1040 | B41: 46228 | C41: P107 | D41: 4 | E41: 9.99 | F41: R01 | H41: =IF(D41="","",D41*E41) -> 39.96 | I41: =_xlfn.XLOOKUP(C41,Products!$A$2:$A$9,Products!$B$2:$B$9,"Not Found") -> USB Cable
A42: S1041 | B42: 46210 | C42: P104 | D42: 1 | E42: 5.99 | F42: R04 | H42: =IF(D42="","",D42*E42) -> 5.99 | I42: =_xlfn.XLOOKUP(C42,Products!$A$2:$A$9,Products!$B$2:$B$9,"Not Found") -> Notebook
A43: S1042 | B43: 46217 | C43: P101 | D43: 3 | E43: 49.99 | F43: R03 | H43: =IF(D43="","",D43*E43) -> 149.97 | I43: =_xlfn.XLOOKUP(C43,Products!$A$2:$A$9,Products!$B$2:$B$9,"Not Found") -> Coffee Maker
A44: S1043 | B44: 46224 | C44: P106 | D44: 5 | E44: 39.99 | F44: R02 | H44: =IF(D44="","",D44*E44) -> 199.95 | I44: =_xlfn.XLOOKUP(C44,Products!$A$2:$A$9,Products!$B$2:$B$9,"Not Found") -> Headphones
A45: S1044 | B45: 46206 | C45: P103 | D45: 2 | E45: 25 | F45: R01 | H45: =IF(D45="","",D45*E45) -> 50 | I45: =_xlfn.XLOOKUP(C45,Products!$A$2:$A$9,Products!$B$2:$B$9,"Not Found") -> Desk Lamp
A46: S1045 | B46: 46213 | C46: P108 | D46: 4 | E46: 18.99 | F46: R04 | H46: =IF(D46="","",D46*E46) -> 75.96 | I46: =_xlfn.XLOOKUP(C46,Products!$A$2:$A$9,Products!$B$2:$B$9,"Not Found") -> Desk Organizer
A47: S1046 | B47: 46220 | C47: P105 | D47: 1 | E47: 14.5 | F47: R03 | H47: =IF(D47="","",D47*E47) -> 14.5 | I47: =_xlfn.XLOOKUP(C47,Products!$A$2:$A$9,Products!$B$2:$B$9,"Not Found") -> Water Bottle
A48: S1047 | B48: 46227 | C48: P102 | D48: 3 | E48: 59.99 | F48: R02 | H48: =IF(D48="","",D48*E48) -> 179.97 | I48: =_xlfn.XLOOKUP(C48,Products!$A$2:$A$9,Products!$B$2:$B$9,"Not Found") -> Blender
A49: S1048 | B49: 46209 | C49: P107 | D49: 5 | E49: 9.99 | F49: R01 | H49: =IF(D49="","",D49*E49) -> 49.95 | I49: =_xlfn.XLOOKUP(C49,Products!$A$2:$A$9,Products!$B$2:$B$9,"Not Found") -> USB Cable
... A59: S1058 | B59: 46260 | C59: P102 | D59: 5 | E59: 59.99 | F59: R04 | H59: =IF(D59="","",D59*E59) -> 299.95 | I59: =_xlfn.XLOOKUP(C59,Products!$A$2:$A$9,Products!$B$2:$B$9,"Not Found") -> Blender
...

Sheet Pivot Table
A5: Row Labels | B5: Sum of Revenue
A6: 4/16/26 - 4/22/26 | B6: 179.97
A7: 4/2/26 - 4/8/26 | B7: 264.94
A8: 4/23/26 - 4/29/26 | B8: 67.93
A9: 4/30/26 - 5/6/26 | B9: 106.93
A10: 4/9/26 - 4/15/26 | B10: 339.92
A11: 5/14/26 - 5/20/26 | B11: 269.96
A12: 5/21/26 - 5/27/26 | B12: 200.91
A13: 5/28/26 - 6/3/26 | B13: 18.99
A14: 5/7/26 - 5/13/26 | B14: 414.41
A15: 6/11/26 - 6/17/26 | B15: 407.94
A16: 6/18/26 - 6/24/26 | B16: 239.95
A17: 6/25/26 - 7/1/26 | B17: 125
... A31: Grand Total | B31: 5701.48

Sheet Detail1
A1: Details for Sum of Revenue - productname: USB Cable
A3: SaleID | B3: SaleDate | C3: ProductID | D3: Quantity | E3: UnitPrice | F3: RegionID | G3: dataqaulity_status | H3: Revenue | I3: productname
A4: S1070 | B4: 46275 | C4: P107 | D4: 4 | E4: 9.99 | F4: R01 | H4: 39.96 | I4: USB Cable
A5: S1062 | B5: 46269 | C5: P107 | D5: 3 | E5: 9.99 | F5: R01 | H5: 29.97 | I5: USB Cable
A6: S1059 | B6: 46242 | C6: P107 | D6: -2 | E6: 9.99 | F6: R03 | G6: Confirmed Return | H6: -19.98 | I6: USB Cable
A7: S1051 | B7: 46236 | C7: P107 | D7: 1 | E7: 9.99 | F7: R03 | H7: 9.99 | I7: USB Cable
A8: S1048 | B8: 46209 | C8: P107 | D8: 5 | E8: 9.99 | F8: R01 | H8: 49.95 | I8: USB Cable
A9: S1040 | B9: 46228 | C9: P107 | D9: 4 | E9: 9.99 | F9: R01 | H9: 39.96 | I9: USB Cable
A10: S1007 | B10: 46131 | C10: P107 | D10: 3 | E10: 9.99 | F10: R03 | H10: 29.97 | I10: USB Cable
A11: S1029 | B11: 46196 | C11: P107 | D11: 2 | E11: 9.99 | F11: R03 | H11: 19.98 | I11: USB Cable
A12: S1018 | B12: 46163 | C12: P107 | D12: 5 | E12: 9.99 | F12: R01 | H12: 49.95 | I12: USB Cable

Sheet Sales
A1: SaleID | B1: SaleDate | C1: ProductID | D1: Quantity | E1: UnitPrice | F1: RegionID
A2: S1001 | B2: 46114 | C2: P101 | D2: 1 | E2: 49.99 | F2: R01
A3: S1002 | B3: 46121 | C3: P106 | D3: 3 | E3: 39.99 | F3: R04
A4: S1003 | B4: 46128 | C4: P103 | D4: 5 | E4: 25 | F4: R03
A5: S1004 | B5: 46135 | C5: P108 | D5: 2 | E5: 18.99 | F5: R02
A6: S1005 | B6: 46117 | C6: P105 | D6: 4 | E6: 14.5 | F6: R01
A7: S1006 | B7: 46124 | C7: P102 | D7: 1 | E7: 59.99 | F7: R04
A8: S1007 | B8: 46131 | C8: P107 | D8: 3 | E8: 9.99 | F8: R03
A9: S1008 | B9: 46138 | C9: P104 | D9: 5 | E9: 5.99 | F9: R02
A10: S1009 | B10: 46120 | C10: P101 | D10: 2 | E10: 49.99 | F10: R01
A11: S1010 | B11: 46127 | C11: P106 | D11: 4 | E11: 39.99 | F11: R04
A12: S1011 | B12: 46134 | C12: P103 | D12: 1 | E12: 25 | F12: R03
A13: S1012 | B13: 46116 | C13: P108 | D13: 3 | E13: 18.99 | F13: R02
... A24: S1023 | B24: 46148 | C24: P108 | D24: 5 | E24: 18.99 | F24: R04
A25: S1024 | B25: 46155 | C25: P105 | E25: 14.5 | F25: R03
A26: S1025 | B26: 46193 | C26: P103 | D26: 4 | E26: 25 | F26: R03
A27: S1026 | B27: 46175 | C27: P108 | D27: 1 | E27: 18.99 | F27: R02
A28: S1027 | B28: 46182 | C28: P105 | D28: 3 | E28: 14.5 | F28: R01
A29: S1028 | B29: 46189 | C29: P102 | D29: 5 | E29: 59.99 | F29: R04
A30: S1029 | B30: 46196 | C30: P107 | D30: 2 | E30: 9.99 | F30: R03
A31: S1030 | B31: 46178 | C31: P104 | D31: 4 | E31: 5.99 | F31: R02
A32: S1031 | B32: 46185 | C32: P101 | D32: 1 | E32: 49.99 | F32: R01
A33: S1032 | B33: 46192 | C33: P106 | D33: 3 | E33: 39.99 | F33: R04
A34: S1033 | B34: 46199 | C34: P103 | D34: 5 | E34: 25 | F34: R03
A35: S1034 | B35: 46181 | C35: P108 | D35: 2 | E35: 18.99 | F35: R02
A36: S1035 | B36: 46188 | C36: P105 | D36: 4 | E36: 14.5 | F36: R01
A37: S1036 | B37: 46195 | C37: P102 | D37: 1 | E37: 0 | F37: R04
... A73: S1072 | B73: 46289 | C73: P101 | D73: 3 | E73: 49.99 | F73: R03

Sheet Products
A1: ProductID | B1: ProductName | C1: Category | D1: CostPrice
A2: P101 | B2: Coffee Maker | C2: Appliances | D2: 24.5
A3: P102 | B3: Blender | C3: Appliances | D3: 29
A4: P103 | B4: Desk Lamp | C4: Home | D4: 12
A5: P104 | B5: Notebook | C5: Office | D5: 2.2
A6: P105 | B6: Water Bottle | C6: Home | D6: 6.5
A7: P106 | B7: Headphones | C7: Electronics | D7: 18
A8: P107 | B8: USB Cable | C8: Electronics | D8: 3.1
A9: P108 | B9: Desk Organizer | C9: Office | D9: 7.2

Sheet Regions
A1: RegionID | B1: RegionName | C1: State
A2: R01 | B2: North | C2: TX
A3: R02 | B3: South | C3: TX
A4: R03 | B4: East | C4: TX
A5: R04 | B5: West | C5: TX

Sheet Business Report
A1: Organized Findings
A5: Area | B5: Key Findings
A6: Overall revenue | B6: Decreased $243.05 (22.2%) from August to September
A7: Product performance | B7: Blender revenue declined $359.94
A8: Regional performance | B8: R04 (West) revenue declined $526.98
A9: Product + region | B9: R04 sold 9 Blenders in August and 0 in September
A10: Weekly performance | B10: August's highest and lowest seven-day periods differed by $602.91
A11: Root cause | B11: Not established by available data
A16: MetroMart Sales Performance — Executive Summary
A19: MetroMart Sales Performance — Executive Summary
A21: MetroMart's revenue declined from $1,093.27 in August to $850.22 in September 2026, representing a 22.2% decrease.
A23: The decline was primarily associated with weaker performance in the West region (R04), where revenue fell by $526.98. Blender sales were a significant contributor, with R04 selling nine units in August and none in September.
A25: Although other products and regions partially offset these losses, the available data does not establish the underlying cause of the decline.
A27: Management should investigate inventory availability, customer demand, and promotional activity before implementing corrective measures.
